<?xml version="1.0" encoding="utf-8"?>
<robot name="fsrobo_r">
  <link name="world"/>
  <joint name="world_joint" type="fixed">
    <parent link="world" />
    <child link = "base_link" />
  </joint>
  <link
    name="base_link">
    <inertial>
      <origin
        xyz="-8.2154E-06 -0.0096388 0.032182"
        rpy="0 0 0" />
      <mass
        value="0.2733" />
      <inertia
        ixx="0.0005002"
        ixy="-8.4689E-08"
        ixz="2.8655E-08"
        iyy="0.00054063"
        iyz="1.3738E-05"
        izz="0.00076675" />
    </inertial>
    <visual>
      <origin
        xyz="0 0 0"
        rpy="0 0 0" />
      <geometry>
        <mesh
          filename="package://fsrobo_r_description/meshes/base_link.STL" />
      </geometry>
      <material
        name="">
        <color
          rgba="0.79216 0.81961 0.93333 1" />
      </material>
    </visual>
    <collision>
      <origin
        xyz="0 0 0"
        rpy="0 0 0" />
      <geometry>
        <mesh
          filename="package://fsrobo_r_description/meshes/base_link.STL" />
      </geometry>
    </collision>
  </link>
  <link
    name="Link1">
    <inertial>
      <origin
        xyz="-0.0047711 4.2955E-05 0.12508"
        rpy="0 0 0" />
      <mass
        value="0.57284" />
      <inertia
        ixx="0.00086897"
        ixy="1.1456E-06"
        ixz="3.1692E-05"
        iyy="0.00086624"
        iyz="-1.6369E-07"
        izz="0.0013138" />
    </inertial>
    <visual>
      <origin
        xyz="0 0 0"
        rpy="0 0 0" />
      <geometry>
        <mesh
          filename="package://fsrobo_r_description/meshes/Link1.STL" />
      </geometry>
      <material
        name="">
        <color
          rgba="0.79216 0.81961 0.93333 1" />
      </material>
    </visual>
    <collision>
      <origin
        xyz="0 0 0"
        rpy="0 0 0" />
      <geometry>
        <mesh
          filename="package://fsrobo_r_description/meshes/Link1.STL" />
      </geometry>
    </collision>
  </link>
  <joint
    name="Joint1"
    type="revolute">
    <origin
      xyz="0 0 0"
      rpy="0 0 0" />
    <parent
      link="base_link" />
    <child
      link="Link1" />
    <axis
      xyz="0 0 1" />
    <limit
      lower="-4.1888"
      upper="4.1888"
      effort="300"
      velocity="3.1105" />
  </joint>
  <link
    name="Link2">
    <inertial>
      <origin
        xyz="-0.119709681675927 -2.8819585606854E-12 0.245036338887227"
        rpy="0 0 0" />
      <mass
        value="1.49263003075435" />
      <inertia
        ixx="0.00466949460312344"
        ixy="-6.39423301650995E-14"
        ixz="-3.75564636935713E-14"
        iyy="0.00377443823961919"
        iyz="2.29119615606559E-06"
        izz="0.00250584432523859" />
    </inertial>
    <visual>
      <origin
        xyz="0 0 0"
        rpy="0 0 0" />
      <geometry>
        <mesh
          filename="package://fsrobo_r_description/meshes/Link2.STL" />
      </geometry>
      <material
        name="">
        <color
          rgba="0.792156862745098 0.819607843137255 0.933333333333333 1" />
      </material>
    </visual>
    <collision>
      <origin
        xyz="0 0 0"
        rpy="0 0 0" />
      <geometry>
        <mesh
          filename="package://fsrobo_r_description/meshes/Link2.STL" />
      </geometry>
    </collision>
  </link>
  <joint
    name="Joint2"
    type="revolute">
    <origin
      xyz="0 0 0.145"
      rpy="0 0 0" />
    <parent
      link="Link1" />
    <child
      link="Link2" />
    <axis
      xyz="1 0 0" />
    <limit
      lower="-4.1888"
      upper="4.1888"
      effort="300"
      velocity="3.1105" />
  </joint>
  <link
    name="Link3">
    <inertial>
      <origin
        xyz="-0.0232169312438168 -3.62221257994844E-05 0.00922252200571338"
        rpy="0 0 0" />
      <mass
        value="0.279214025610625" />
      <inertia
        ixx="0.000290151876219787"
        ixy="-3.1123143368769E-07"
        ixz="-8.38376046880362E-06"
        iyy="0.000220751797899869"
        iyz="3.3029089119022E-08"
        izz="0.000289276910204893" />
    </inertial>
    <visual>
      <origin
        xyz="0 0 0"
        rpy="0 0 0" />
      <geometry>
        <mesh
          filename="package://fsrobo_r_description/meshes/Link3.STL" />
      </geometry>
      <material
        name="">
        <color
          rgba="0.792156862745098 0.819607843137255 0.933333333333333 1" />
      </material>
    </visual>
    <collision>
      <origin
        xyz="0 0 0"
        rpy="0 0 0" />
      <geometry>
        <mesh
          filename="package://fsrobo_r_description/meshes/Link3.STL" />
      </geometry>
    </collision>
  </link>
  <joint
    name="Joint3"
    type="revolute">
    <origin
      xyz="0 0 0.49"
      rpy="0 0 0" />
    <parent
      link="Link2" />
    <child
      link="Link3" />
    <axis
      xyz="1 0 0" />
    <limit
      lower="-12.1888"
      upper="4.1888"
      effort="300"
      velocity="3.1105" />
  </joint>
  <link
    name="Link4">
    <inertial>
      <origin
        xyz="0.00702527277849463 -2.97821441574558E-05 -0.0887140110734381"
        rpy="0 0 0" />
      <mass
        value="0.365046230571819" />
      <inertia
        ixx="0.000595488874854694"
        ixy="-1.34848592189982E-06"
        ixz="-8.28408688782746E-06"
        iyy="0.000528321288030801"
        iyz="3.13708256033819E-08"
        izz="0.000274022415362295" />
    </inertial>
    <visual>
      <origin
        xyz="0 0 0"
        rpy="0 0 0" />
      <geometry>
        <mesh
          filename="package://fsrobo_r_description/meshes/Link4.STL" />
      </geometry>
      <material
        name="">
        <color
          rgba="0.792156862745098 0.819607843137255 0.933333333333333 1" />
      </material>
    </visual>
    <collision>
      <origin
        xyz="0 0 0"
        rpy="0 0 0" />
      <geometry>
        <mesh
          filename="package://fsrobo_r_description/meshes/Link4.STL" />
      </geometry>
    </collision>
  </link>
  <joint
    name="Joint4"
    type="revolute">
    <origin
      xyz="0 0 0.37"
      rpy="0 0 0" />
    <parent
      link="Link3" />
    <child
      link="Link4" />
    <axis
      xyz="0 0 1" />
    <limit
      lower="-4.1888"
      upper="4.1888"
      effort="300"
      velocity="3.1105" />
  </joint>
  <link
    name="Link5">
    <inertial>
      <origin
        xyz="-0.00775950758842528 -5.30762371216825E-05 0.0132169097092152"
        rpy="0 0 0" />
      <mass
        value="0.194919797054597" />
      <inertia
        ixx="0.000124655481737484"
        ixy="-3.09722897987843E-07"
        ixz="-8.39143733774032E-06"
        iyy="0.000135838477030009"
        iyz="3.91755878779929E-08"
        izz="0.000204333620678206" />
    </inertial>
    <visual>
      <origin
        xyz="0 0 0"
        rpy="0 0 0" />
      <geometry>
        <mesh
          filename="package://fsrobo_r_description/meshes/Link5.STL" />
      </geometry>
      <material
        name="">
        <color
          rgba="0.792156862745098 0.819607843137255 0.933333333333333 1" />
      </material>
    </visual>
    <collision>
      <origin
        xyz="0 0 0"
        rpy="0 0 0" />
      <geometry>
        <mesh
          filename="package://fsrobo_r_description/meshes/Link5.STL" />
      </geometry>
    </collision>
  </link>
  <joint
    name="Joint5"
    type="revolute">
    <origin
      xyz="0.1 0 0"
      rpy="0 0 0" />
    <parent
      link="Link4" />
    <child
      link="Link5" />
    <axis
      xyz="1 0 0" />
    <limit
      lower="-4.1888"
      upper="4.1888"
      effort="300"
      velocity="3.1105" />
  </joint>
  <link
    name="Link6">
    <inertial>
      <origin
        xyz="-0.000104772377895329 0.000273634815625493 -0.0100488927318354"
        rpy="0 0 0" />
      <mass
        value="0.0366940608517239" />
      <inertia
        ixx="1.4549374301922E-05"
        ixy="6.5460274198039E-08"
        ixz="7.21885364017913E-09"
        iyy="1.42236863506252E-05"
        iyz="-4.89048791503215E-09"
        izz="2.69037893861932E-05" />
    </inertial>
    <visual>
      <origin
        xyz="0 0 0"
        rpy="0 0 0" />
      <geometry>
        <mesh
          filename="package://fsrobo_r_description/meshes/Link6.STL" />
      </geometry>
      <material
        name="">
        <color
          rgba="0.792156862745098 0.819607843137255 0.933333333333333 1" />
      </material>
    </visual>
    <collision>
      <origin
        xyz="0 0 0"
        rpy="0 0 0" />
      <geometry>
        <mesh
          filename="package://fsrobo_r_description/meshes/Link6.STL" />
      </geometry>
    </collision>
  </link>
  <joint
    name="Joint6"
    type="revolute">
    <origin
      xyz="0 0 0.065"
      rpy="0 0 -1.5708" />
    <parent
      link="Link5" />
    <child
      link="Link6" />
    <axis
      xyz="0 0 1" />
    <limit
      lower="-4.1888"
      upper="4.1888"
      effort="300"
      velocity="3.1105" />
  </joint>

  <gazebo>
    <plugin name="force_joint" filename="libforce_joint.so"/>
  </gazebo>

  <gazebo reference="base_link">
    <selfCollide>true</selfCollide>
  </gazebo>

  <gazebo reference="Link1">
    <selfCollide>true</selfCollide>
  </gazebo>

  <gazebo reference="Link2">
    <selfCollide>true</selfCollide>
  </gazebo>

  <gazebo reference="Link3">
    <selfCollide>true</selfCollide>
  </gazebo>

  <gazebo reference="Link4">
    <selfCollide>true</selfCollide>
  </gazebo>

  <gazebo reference="Link5">
    <selfCollide>true</selfCollide>
  </gazebo>

  <gazebo reference="Link6">
    <selfCollide>true</selfCollide>
  </gazebo>

</robot>
